Workbook
Name Slicer_Category: #N/A
Name Slicer_Region: #N/A
Name Slicer_Sales_Person: #N/A
Name Slicer_Segment: #N/A
Name Slicer_State: #N/A
Name Slicer_Sub_Category: #N/A
Name Slicer_year: #N/A

Sheet SalesData
A1: Order ID | B1: Order Date | C1: Customer Name | D1: Region | E1: State | F1: Category | G1: Sub Category | H1: Product Name | I1: Sales | J1: Quantity | K1: Discount | L1: Profit | M1: Sales Person | N1: Segment | O1: order_date_new | P1: year | Q1: month | R1: month_name | S1: Discount Bucket | T1: Profit margin% | U1: Running total | V1: Column1
A2: ORD100002 | B2: 2025-01-31 | C2: Customer 87 | D2: South | E2: Karnataka | F2: Office Supplies | G2: Binders | H2: Document Case | I2: 5565.9 | J2: 10 | K2: 0 | L2: 421.59 | M2: Amit | N2: Home Office | O2: =TEXT(B2,"dd/mm/yyyy") -> 31/01/2025 | P2: =YEAR(O2) -> 2025 | Q2: =MONTH(O2) -> 1 | R2: =TEXT(O2,"mmmm") -> January | S2: =IF(K2=0,"No Discount",IF(K2>=0.1,"Low",IF(K2>=0.2,"Medium","High"))) -> No Discount | T2: =SUM(L2)/SUM(I2) -> 0.075745163 | U2: =SUM($I$2:I2) -> 5565.9 | V2: =Table1[[#This Row],[Running total ]]/SUM(I:I) -> 0.0016061094
A3: ORD100003 | B3: 2025-02-08 | C3: Customer 64 | D3: West | E3: Gujarat | F3: Office Supplies | G3: Writing | H3: Highlighter | I3: 997.04 | J3: 4 | K3: 0.25 | L3: -161.72 | M3: Vikram | N3: Consumer | O3: =TEXT(B3,"dd/mm/yyyy") -> 08/02/2025 | P3: =YEAR(O3) -> 2025 | Q3: =MONTH(O3) -> 2 | R3: =TEXT(O3,"mmmm") -> February | S3: =IF(K3=0,"No Discount",IF(K3>=0.1,"Low",IF(K3>=0.2,"Medium","High"))) -> Low | T3: =SUM(L3)/SUM(I3) -> -0.16220011 | U3: =SUM($I$2:I3) -> 6562.94 | V3: =Table1[[#This Row],[Running total ]]/SUM(I:I) -> 0.0018938177
A4: ORD100004 | B4: 2025-10-31 | C4: Customer 49 | D4: West | E4: Gujarat | F4: Office Supplies | G4: Paper | H4: Notebook | I4: 1711.71 | J4: 7 | K4: 0 | L4: 356.91 | M4: Priya | N4: Small Business | O4: =TEXT(B4,"dd/mm/yyyy") -> 31/10/2025 | P4: =YEAR(O4) -> 2025 | Q4: =MONTH(O4) -> 10 | R4: =TEXT(O4,"mmmm") -> October | S4: =IF(K4=0,"No Discount",IF(K4>=0.1,"Low",IF(K4>=0.2,"Medium","High"))) -> No Discount | T4: =SUM(L4)/SUM(I4) -> 0.20851079 | U4: =SUM($I$2:I4) -> 8274.65 | V4: =Table1[[#This Row],[Running total ]]/SUM(I:I) -> 0.0023877528
A5: ORD100005 | B5: 2025-03-26 | C5: Customer 75 | D5: West | E5: Rajasthan | F5: Office Supplies | G5: Paper | H5: Notebook | I5: 1435.1 | J5: 5 | K5: 0.3 | L5: -122.01 | M5: Pooja | N5: Consumer | O5: =TEXT(B5,"dd/mm/yyyy") -> 26/03/2025 | P5: =YEAR(O5) -> 2025 | Q5: =MONTH(O5) -> 3 | R5: =TEXT(O5,"mmmm") -> March | S5: =IF(K5=0,"No Discount",IF(K5>=0.1,"Low",IF(K5>=0.2,"Medium","High"))) -> Low | T5: =SUM(L5)/SUM(I5) -> -0.085018466 | U5: =SUM($I$2:I5) -> 9709.75 | V5: =Table1[[#This Row],[Running total ]]/SUM(I:I) -> 0.0028018687
A6: ORD100006 | B6: 2025-02-10 | C6: Customer 191 | D6: North | E6: Punjab | F6: Office Supplies | G6: Writing | H6: Pen Pack | I6: 1413.08 | J6: 2 | K6: 0.1 | L6: 416.9 | M6: Vikram | N6: Home Office | O6: =TEXT(B6,"dd/mm/yyyy") -> 10/02/2025 | P6: =YEAR(O6) -> 2025 | Q6: =MONTH(O6) -> 2 | R6: =TEXT(O6,"mmmm") -> February | S6: =IF(K6=0,"No Discount",IF(K6>=0.1,"Low",IF(K6>=0.2,"Medium","High"))) -> Low | T6: =SUM(L6)/SUM(I6) -> 0.2950293 | U6: =SUM($I$2:I6) -> 11122.83 | V6: =Table1[[#This Row],[Running total ]]/SUM(I:I) -> 0.0032096304
A7: ORD100007 | B7: 2024-12-03 | C7: Customer 166 | D7: South | E7: Tamil Nadu | F7: Furniture | G7: Chairs | H7: Gaming Chair | I7: 6869.16 | J7: 9 | K7: 0 | L7: 721.16 | M7: Pooja | N7: Home Office | O7: =TEXT(B7,"dd/mm/yyyy") -> 03/12/2024 | P7: =YEAR(O7) -> 2024 | Q7: =MONTH(O7) -> 12 | R7: =TEXT(O7,"mmmm") -> December | S7: =IF(K7=0,"No Discount",IF(K7>=0.1,"Low",IF(K7>=0.2,"Medium","High"))) -> No Discount | T7: =SUM(L7)/SUM(I7) -> 0.10498518 | U7: =SUM($I$2:I7) -> 17991.99 | V7: =Table1[[#This Row],[Running total ]]/SUM(I:I) -> 0.0051918117
A8: ORD100008 | B8: 2024-10-15 | C8: Customer 167 | D8: West | E8: Maharashtra | F8: Furniture | G8: Chairs | H8: Visitor Chair | I8: 5509.7 | J8: 10 | K8: 0.2 | L8: -457.71 | M8: Karan | N8: Home Office | O8: =TEXT(B8,"dd/mm/yyyy") -> 15/10/2024 | P8: =YEAR(O8) -> 2024 | Q8: =MONTH(O8) -> 10 | R8: =TEXT(O8,"mmmm") -> October | S8: =IF(K8=0,"No Discount",IF(K8>=0.1,"Low",IF(K8>=0.2,"Medium","High"))) -> Low | T8: =SUM(L8)/SUM(I8) -> -0.083073489 | U8: =SUM($I$2:I8) -> 23501.69 | V8: =Table1[[#This Row],[Running total ]]/SUM(I:I) -> 0.0067817039
A9: ORD100009 | B9: 2025-09-03 | C9: Customer 94 | D9: West | E9: Gujarat | F9: Technology | G9: Computers | H9: Laptop | I9: 4643.04 | J9: 6 | K9: 0.25 | L9: -634.04 | M9: Karan | N9: Consumer | O9: =TEXT(B9,"dd/mm/yyyy") -> 03/09/2025 | P9: =YEAR(O9) -> 2025 | Q9: =MONTH(O9) -> 9 | R9: =TEXT(O9,"mmmm") -> September | S9: =IF(K9=0,"No Discount",IF(K9>=0.1,"Low",IF(K9>=0.2,"Medium","High"))) -> Low | T9: =SUM(L9)/SUM(I9) -> -0.13655708 | U9: =SUM($I$2:I9) -> 28144.73 | V9: =Table1[[#This Row],[Running total ]]/SUM(I:I) -> 0.0081215106
A10: ORD100010 | B10: 2024-10-02 | C10: Customer 39 | D10: North | E10: Uttarakhand | F10: Furniture | G10: Storage | H10: Cabinet | I10: 101.16 | J10: 6 | K10: 0.3 | L10: -23.27 | M10: Vikram | N10: Corporate | O10: =TEXT(B10,"dd/mm/yyyy") -> 02/10/2024 | P10: =YEAR(O10) -> 2024 | Q10: =MONTH(O10) -> 10 | R10: =TEXT(O10,"mmmm") -> October | S10: =IF(K10=0,"No Discount",IF(K10>=0.1,"Low",IF(K10>=0.2,"Medium","High"))) -> Low | T10: =SUM(L10)/SUM(I10) -> -0.23003163 | U10: =SUM($I$2:I10) -> 28245.89 | V10: =Table1[[#This Row],[Running total ]]/SUM(I:I) -> 0.0081507016
A11: ORD100011 | B11: 2024-07-11 | C11: Customer 196 | D11: South | E11: Telangana | F11: Technology | G11: Computers | H11: Laptop | I11: 2687.4 | J11: 10 | K11: 0.15 | L11: 145.56 | M11: Priya | N11: Consumer | O11: =TEXT(B11,"dd/mm/yyyy") -> 11/07/2024 | P11: =YEAR(O11) -> 2024 | Q11: =MONTH(O11) -> 7 | R11: =TEXT(O11,"mmmm") -> July | S11: =IF(K11=0,"No Discount",IF(K11>=0.1,"Low",IF(K11>=0.2,"Medium","High"))) -> Low | T11: =SUM(L11)/SUM(I11) -> 0.054163876 | U11: =SUM($I$2:I11) -> 30933.29 | V11: =Table1[[#This Row],[Running total ]]/SUM(I:I) -> 0.0089261841
A12: ORD100012 | B12: 2024-03-17 | C12: Customer 26 | D12: North | E12: Haryana | F12: Technology | G12: Phones | H12: Smartphone | I12: 1715.22 | J12: 3 | K12: 0.15 | L12: 175.1 | M12: Rahul | N12: Corporate | O12: =TEXT(B12,"dd/mm/yyyy") -> 17/03/2024 | P12: =YEAR(O12) -> 2024 | Q12: =MONTH(O12) -> 3 | R12: =TEXT(O12,"mmmm") -> March | S12: =IF(K12=0,"No Discount",IF(K12>=0.1,"Low",IF(K12>=0.2,"Medium","High"))) -> Low | T12: =SUM(L12)/SUM(I12) -> 0.10208603 | U12: =SUM($I$2:I12) -> 32648.51 | V12: =Table1[[#This Row],[Running total ]]/SUM(I:I) -> 0.0094211321
A13: ORD100013 | B13: 2024-05-16 | C13: Customer 100 | D13: West | E13: Gujarat | F13: Office Supplies | G13: Paper | H13: Notebook | I13: 572.04 | J13: 1 | K13: 0.15 | L13: 117.9 | M13: Pooja | N13: Home Office | O13: =TEXT(B13,"dd/mm/yyyy") -> 16/05/2024 | P13: =YEAR(O13) -> 2024 | Q13: =MONTH(O13) -> 5 | R13: =TEXT(O13,"mmmm") -> May | S13: =IF(K13=0,"No Discount",IF(K13>=0.1,"Low",IF(K13>=0.2,"Medium","High"))) -> Low | T13: =SUM(L13)/SUM(I13) -> 0.20610447 | U13: =SUM($I$2:I13) -> 33220.55 | V13: =Table1[[#This Row],[Running total ]]/SUM(I:I) -> 0.0095862014
... A1001: ORD101001 | B1001: 2024-11-15 | C1001: Customer 144 | D1001: West | E1001: Rajasthan | F1001: Furniture | G1001: Tables | H1001: Conference Table | I1001: 5809.85 | J1001: 5 | K1001: 0.15 | L1001: 1528.75 | M1001: Karan | N1001: Home Office | O1001: =TEXT(B1001,"dd/mm/yyyy") -> 15/11/2024 | P1001: =YEAR(O1001) -> 2024 | Q1001: =MONTH(O1001) -> 11 | R1001: =TEXT(O1001,"mmmm") -> November | S1001: =IF(K1001=0,"No Discount",IF(K1001>=0.1,"Low",IF(K1001>=0.2,"Medium","High"))) -> Low | T1001: =SUM(L1001)/SUM(I1001) -> 0.26313072 | U1001: =SUM($I$2:I1001) -> 3465455.1 | V1001: =Table1[[#This Row],[Running total ]]/SUM(I:I) -> 1

Sheet Sheet1
I1: KPI CARDS Total Sales • Total Profit • Orders • Quantity • Profit Margin • Average Order Value
A3: KPI Cards
A6: Sum of Sales | B6: Count of Order ID | C6: Sum of Quantity | D6: Average of Profit margin% | E6: Avg order value
A7: 329513.5 | B7: 102 | C7: 546 | D7: 0.11714048 | E7: =GETPIVOTDATA("Sum of Sales",$A$6)/GETPIVOTDATA("Count of Order ID",$A$6) -> 3230.5245
I13: Monthly Sales Trend (Line) • Monthly Profit Trend (Line) • Sales by Region (Bar) • Profit by Category (Column) • Sales by Segment (Donut) • Top 10 Products (Bar) • Top 10 Customers (Bar) • Salesperson Performance (Column) • Discount vs Profit (Scatter) • Pareto Chart (Combo
A16: Row Labels | B16: Sum of Sales | C16: Sum of Profit
A17: March | B17: 74572.57 | C17: 11122.75
A18: January | B18: 38708.35 | C18: 5955.53
A19: July | B19: 37760.22 | C19: 4396.35
A20: September | B20: 35293.36 | C20: 4047.75
A21: August | B21: 29950.8 | C21: 3758.2
A22: April | B22: 27424.12 | C22: 2854.67
A23: December | B23: 19015.85 | C23: 1445.02
A24: October | B24: 15954.68 | C24: 2817.24
A25: May | B25: 15478.75 | C25: 390.38
A26: November | B26: 12968.55 | C26: 1157.1
A27: June | B27: 12168.48 | C27: 3981.5
A28: February | B28: 10217.77 | C28: 1591.69
A29: Grand Total | B29: 329513.5 | C29: 43518.18
A35: Sum of Profit
A36: 43518.18
A41: Row Labels | B41: Sum of Sales
A42: West | B42: 118999.8
A43: North | B43: 112921.44
A44: East | B44: 97592.26
A45: Grand Total | B45: 329513.5
A50: Row Labels | B50: Sum of Profit
A51: Technology | B51: 17955.63
A52: Furniture | B52: 13106.81
A53: Office Supplies | B53: 12455.74
A54: Grand Total | B54: 43518.18
A59: Row Labels | B59: Sum of Sales
A60: Consumer | B60: 106760.3
A61: Corporate | B61: 97646.81
A62: Home Office | B62: 62873.43
A63: Small Business | B63: 62232.96
A64: Grand Total | B64: 329513.5
A70: Row Labels | B70: Sum of Sales
A71: Sticky Notes | B71: 22356.15
A72: Headset | B72: 21802.05
...

Sheet Sheet2
A1: =GETPIVOTDATA("Sum of Sales",Sheet1!$A$6) -> 329513.5 | E1: =GETPIVOTDATA("Profit",Sheet1!$A$35) -> 43518.18 | I1: =Sheet1!E7 -> 3230.5245 | M1: =GETPIVOTDATA("Count of Order ID",Sheet1!$A$6) -> 102 | Q1: =GETPIVOTDATA("Sum of Quantity",Sheet1!$A$6) -> 546 | U1: =GETPIVOTDATA("Average of Profit margin%",Sheet1!$A$6) -> 0.11714048
